Workbook
Name \A: #REF!
Name \A: #REF!
Name \C: #REF!
Name \C: #REF!
Name \D: #REF!
Name \D: #REF!
Name \E: #REF!
Name \E: #REF!
Name \F: #REF!
Name \F: #REF!
Name \G: #REF!
Name \G: #REF!
Name \H: #REF!
Name \H: #REF!
Name \J: #REF!
Name \J: #REF!
Name \M: #REF!
Name \M: #REF!
Name \N: #REF!
Name \N: #REF!
Name \P: #REF!
Name \P: #REF!
Name \Q: #REF!
Name \Q: #REF!
Name \R: #REF!
Name \R: #REF!
Name \S: #REF!
Name \S: #REF!
Name \T: #REF!
Name \T: #REF!
Name \V: #REF!
Name \V: #REF!
Name \X: #REF!
Name \X: #REF!
Name _43B: #REF!
Name _43B: #REF!
Name _a1: #REF!
Name _a1: #REF!
Name _aug08: #REF!
Name _aug08: #REF!
Name _C: '[6]Power&Fuel'!#REF!
Name _C: '[6]Power&Fuel'!#REF!
Name _DAT1: #REF!
Name _DAT1: #REF!
Name _DAT10: [7]Input_B_V!$J$2:$J$1028
Name _DAT100: #REF!
Name _DAT100: #REF!
Name _DAT101: #REF!
Name _DAT101: #REF!
Name _DAT102: #REF!
Name _DAT102: #REF!
Name _DAT103: #REF!
Name _DAT103: #REF!
Name _DAT104: #REF!
Name _DAT104: #REF!
Name _DAT105: #REF!
Name _DAT105: #REF!
Name _DAT106: #REF!
Name _DAT106: #REF!
Name _DAT107: #REF!

Sheet Hyderabad
A1: Location | B1: Business | C1: Section | D1: Sr_No | E1: Dept_Machine_Name | F1: Designation | G1: Machine_Count | H1: Manpower_Base_Qty | I1: N_shifts | J1: W | K1: Workload | L1: Formulas | M1: BE_Scientific_Manpower | N1: Operator_Type | O1: Contractors | P1: Company_Associate | Q1: BE_Final_Manpower | R1: General_Shift | S1: Shift_A | T1: Shift_B | U1: Shift_C | V1: Reliever | W1: Remarks
A2: Hyderabad | B2: Flooring | C2: BCF | D2: 1 | E2: BCF | F2: Operator | G2: =Reqd_MC!I2 -> 2.3369737 | I2: 3 | J2: 0.8 | K2: 0.8 operators/machine - 2.5 winders/operator (2 winders/machine) | M2: =IF(MOD(G2*J2,1)<0.3,ROUNDUP(G2*J2*3,0),ROUNDUP(G2*J2,0)*3) -> 6 | Q2: =M2 -> 6
A3: Hyderabad | B3: Flooring | C3: BCF | D3: 2 | E3: BCF | F3: Material Handling | I3: 3 | M3: 3 | Q3: =M3 -> 3
A4: Hyderabad | B4: Flooring | C4: BCF | D4: 3 | E4: BCF | F4: Spinning - Operator | I4: 3 | M4: 4 | Q4: =M4 -> 4
A5: Hyderabad | B5: Flooring | C5: BCF | D5: 4 | E5: BCF | F5: Data Entry | I5: 3 | M5: 0 | Q5: =M5 -> 0
A6: Hyderabad | B6: Flooring | C6: BCF | D6: 5 | E6: BCF | F6: G-Burnout | I6: 3 | M6: 4 | Q6: =M6 -> 4
A7: Hyderabad | B7: Flooring | C7: BCF | D7: 6 | E7: BCF | F7: H-DRYER (BCF+POY) | I7: 3 | M7: 3 | Q7: =M7 -> 3
A8: Hyderabad | B8: Flooring | C8: BCF | D8: 7 | E8: BCF | F8: Chips Charging | I8: 3 | M8: 3 | O8: 1 | Q8: =M8 -> 3
A9: Hyderabad | B9: Flooring | C9: POY | D9: 1 | E9: POY | F9: Operator | G9: =Reqd_MC!I3 -> 12 | H9: 2 | I9: 3 | J9: 0.5 | K9: 0.5 operator/machine | M9: =IF(MOD(G9*J9,1)<0.3,ROUNDUP(G9*J9*3,0),ROUNDUP(G9*J9,0)*3) -> 18 | Q9: =M9 -> 18
A10: Hyderabad | B10: Flooring | C10: POY | D10: 2 | E10: POY | F10: Chips Charging | I10: 3 | M10: 3 | O10: 1 | Q10: =M10 -> 3
A11: Hyderabad | B11: Flooring | C11: POY | D11: 3 | E11: POY | F11: Dryer | I11: 3 | M11: 6 | Q11: =M11 -> 6
A12: Hyderabad | B12: Flooring | C12: POY | D12: 4 | E12: POY | F12: Spinning + Control Room | I12: 3 | M12: 9 | Q12: =M12 -> 9
A13: Hyderabad | B13: Flooring | C13: POY | D13: 5 | E13: POY | F13: Data Entry | I13: 3 | M13: 1 | Q13: =M13 -> 1
A14: Hyderabad | B14: Flooring | C14: POY | D14: 6 | E14: POY | F14: Burn Out | I14: 3 | M14: 6 | Q14: =M14 -> 6
A15: Hyderabad | B15: Flooring | C15: POY | D15: 7 | E15: POY | F15: PD Sample (M/C will install after 5 Month) | I15: 3 | Q15: =M15 -> 0
A16: Hyderabad | B16: Flooring | C16: Texturizing | D16: 1 | E16: Texturizing | F16: Operator | G16: =Reqd_MC!I4 -> 8 | I16: 3 | J16: 2.5625 | K16: 2.5625 operator/machine | M16: =IF(MOD(G16*J16,1)<0.3,ROUNDUP(G16*J16*3,0),ROUNDUP(G16*J16,0)*3) -> 63 | O16: 1 | Q16: =M16 -> 63
A17: Hyderabad | B17: Flooring | C17: Texturizing | D17: 2 | E17: Texturizing | F17: Helper | I17: 3 | M17: 9 | O17: 1 | Q17: =M17 -> 9
A18: Hyderabad | B18: Flooring | C18: Texturizing | D18: 3 | E18: Texturizing | F18: DOE | I18: 3 | O18: 1 | Q18: =M18 -> 0
A19: Hyderabad | B19: Flooring | C19: Texturizing | D19: 4 | E19: Texturizing | F19: Jobber | I19: 3 | M19: 3 | O19: 1 | Q19: =M19 -> 3
A20: Hyderabad | B20: Flooring | C20: Texturizing | D20: 5 | E20: Texturizing | F20: Fitter | I20: 3 | M20: 3 | O20: 1 | Q20: =M20 -> 3
A21: Hyderabad | B21: Flooring | C21: Texturizing | D21: 6 | E21: Texturizing | F21: Material Handler | I21: 3 | M21: 3 | O21: 1 | Q21: =M21 -> 3
A22: Hyderabad | B22: Flooring | C22: Texturizing | D22: 7 | E22: Texturizing | F22: Paper Tube Sagrigation | I22: 3 | M22: 1 | O22: 1 | Q22: =M22 -> 1
A23: Hyderabad | B23: Flooring | C23: Texturizing | D23: 8 | E23: Texturizing | F23: Roping (Mandays) | I23: 3 | M23: 3 | O23: 1 | Q23: =M23 -> 3
A24: Hyderabad | B24: Flooring | C24: Parallel Winding | D24: 1 | E24: Parallel Winding | F24: Operator | G24: =Reqd_MC!H5 -> 4 | I24: 3 | J24: 2 | K24: 2 operator/machine | M24: =IF(MOD(G24*J24,1)<0.3,ROUNDUP(G24*J24*3,0),ROUNDUP(G24*J24,0)*3) -> 24 | O24: 1 | Q24: =M24 -> 24
A25: Hyderabad | B25: Flooring | C25: Parallel Winding | D25: 2 | E25: Parallel Winding | F25: Jobber | I25: 3 | M25: 3 | O25: 1 | Q25: =M25 -> 3
A26: Hyderabad | B26: Flooring | C26: Cabling | D26: 1 | E26: Cabling | F26: Operator | G26: =Reqd_MC!H6 -> 19 | I26: 3 | J26: 1 | K26: 1 operator/machine | M26: =IF(MOD(G26*J26,1)<0.3,ROUNDUP(G26*J26*3,0),ROUNDUP(G26*J26,0)*3) -> 57 | O26: 1 | Q26: =M26 -> 57
A27: Hyderabad | B27: Flooring | C27: Cabling | D27: 2 | E27: Cabling | F27: DOE | I27: 3 | M27: =0 -> 0 | O27: 1 | Q27: =M27 -> 0
A28: Hyderabad | B28: Flooring | C28: Cabling | D28: 3 | E28: Cabling | F28: Jobber | I28: 3 | M28: =1*3 -> 3 | O28: 1 | Q28: =M28 -> 3
A29: Hyderabad | B29: Flooring | C29: Cabling | D29: 4 | E29: Cabling | F29: Fitter | I29: 3 | M29: =1*3 -> 3 | O29: 1 | Q29: =M29 -> 3
A30: Hyderabad | B30: Flooring | C30: Cabling | D30: 5 | E30: Cabling | F30: Material Handler | I30: 3 | M30: =1*3 -> 3 | O30: 1 | Q30: =M30 -> 3
A31: Hyderabad | B31: Flooring | C31: Cabling | D31: 6 | E31: Cabling | F31: Helper | I31: 3 | M31: =1*3 -> 3 | O31: 1 | Q31: =M31 -> 3
A32: Hyderabad | B32: Flooring | C32: Heat Set | D32: 1 | E32: Superba Heat Set | F32: Operator | G32: =Reqd_MC!H7 -> 5 | I32: 3 | J32: 4 | K32: 4 operator/machine | M32: =IF(MOD(G32*J32,1)<0.3,ROUNDUP(G32*J32*3,0),ROUNDUP(G32*J32,0)*3) -> 60 | Q32: =M32 -> 60
A33: Hyderabad | B33: Flooring | C33: Heat Set | D33: 2 | E33: Superba Heat Set | F33: DOE | I33: 3 | M33: 0 | Q33: =M33 -> 0
A34: Hyderabad | B34: Flooring | C34: Heat Set | D34: 3 | E34: Superba Heat Set | F34: Jobber | I34: 3 | M34: 3 | Q34: =M34 -> 3
A35: Hyderabad | B35: Flooring | C35: Heat Set | D35: 4 | E35: Superba Heat Set | F35: Material Handler | I35: 3 | M35: 3 | O35: 1 | Q35: =M35 -> 3
A36: Hyderabad | B36: Flooring | C36: Heat Set | D36: 5 | E36: Superba Heat Set | F36: Paper Tube Sagrgation | I36: 3 | M36: 3 | O36: 1 | Q36: =M36 -> 3
A37: Hyderabad | B37: Flooring | C37: Heat Set | D37: 6 | E37: Superba Heat Set | F37: Fitter | I37: 3 | M37: 3 | Q37: =M37 -> 3
A38: Hyderabad | B38: Flooring | C38: Heat Set | D38: 1 | E38: Power Heat Set | F38: Operator | G38: =Reqd_MC!I8 -> 0.38619961 | I38: 3 | J38: 4 | K38: 4 operator/machine | M38: =IF(G38<=0.33,1,(IF(G38<=0.66,2,3)))*J38 -> 8 | Q38: =M38 -> 8
A39: Hyderabad | B39: Flooring | C39: Printing | D39: 1 | E39: Printing-Chromojet | F39: Operator | G39: =Reqd_MC!I9 -> 1 | I39: 3 | J39: 9 | K39: 9 operator/machine | M39: =IF(G39<=0.33,1,(IF(G39<=0.66,2,3)))*J39 -> 27 | Q39: =M39 -> 27
A40: Hyderabad | B40: Flooring | C40: Printing | D40: 2 | E40: Printing-Chromojet | F40: Sample Machine | I40: 3 | M40: 6 | Q40: =M40 -> 6
...

Sheet BP_Structured
A1: Section | B1: Machine | C1: 46113 | D1: 46143 | E1: 46174 | F1: 46204 | G1: 46235 | H1: 46266 | I1: 46296 | J1: 46327 | K1: 46357 | L1: 46388 | M1: 46419 | N1: 46447 | O1: Units
A2: BCF | B2: BCF | C2: 190053.56 | D2: 227636.66 | E2: 172736.18 | F2: 205578.85 | G2: 250826.71 | H2: 393717.01 | I2: 288952.27 | J2: 367132.62 | K2: 677193.28 | L2: 528044.36 | M2: 487687.57 | N2: 451556.32 | O2: kgs
A3: Cabling | B3: Cabling | C3: 1238788.5 | D3: 1080241.1 | E3: 960682.68 | F3: 1073640.3 | G3: 1193689.2 | H3: 1170212.4 | I3: 1054869.5 | J3: 940619.32 | K3: 1170039.7 | L3: 1163897.3 | M3: 1089413.4 | N3: 1033971.3 | O3: kgs
A4: Heat Set | B4: Power Heat Set | C4: 100470.29 | D4: 77390.829 | E4: 46293.578 | F4: 73043.526 | G4: 77436.854 | H4: 86494.713 | I4: 79944.33 | J4: 125987.81 | K4: 124745.62 | L4: 137266.19 | M4: 131559.38 | N4: 129051.08 | O4: kgs
A5: Heat Set | B5: Superba Heat Set | C5: 1108335.2 | D5: 1028009.1 | E5: 939711.64 | F5: 1001669.9 | G5: 1130540.2 | H5: 1056371.1 | I5: 933369.03 | J5: 920141.58 | K5: 1212098.6 | L5: 992702.54 | M5: 995401.92 | N5: 941464.77 | O5: kgs
A6: POY | B6: POY | C6: 1518410 | D6: 1270519.7 | E6: 1070367.6 | F6: 1503729.6 | G6: 1172241.6 | H6: 1069542.6 | I6: 1159497.9 | J6: 1031857.8 | K6: 1045049.7 | L6: 1046607.1 | M6: 999863.76 | N6: 921180.85 | O6: kgs
A7: Texturizing | B7: Texturizing | C7: 1442558.3 | D7: 1246077.2 | E7: 1159707 | F7: 1249148.5 | G7: 1337464.4 | H7: 1140459.2 | I7: 1164411 | J7: 1032182.3 | K7: 1044370.1 | L7: 1045506.5 | M7: 998580.62 | N7: 924243 | O7: kgs
A8: Parallel Winding | B8: Parallel Winding | C8: 772731.27 | D8: 674690.76 | E8: 607856.38 | F8: 697292.18 | G8: 657301.78 | H8: 634553.79 | I8: 615480.77 | J8: 549635.61 | K8: 663525.89 | L8: 633577.84 | M8: 603487.24 | N8: 608598.74 | O8: kgs
A9: Multiply | B9: Multiply | C9: 96546.648 | D9: 133921.53 | E9: 145860.51 | F9: 105972.23 | G9: 150546.85 | H9: 135954.38 | I9: 147220.99 | J9: 212414.35 | K9: 222519.97 | L9: 119372.29 | M9: 156342.53 | N9: 110249.83 | O9: kgs
A10: Autoclave | B10: Autoclave | C10: 72130.301 | D10: 79680.976 | E10: 73191.572 | F10: 82743.929 | G10: 70744.122 | H10: 73504.265 | I10: 78371.572 | J10: 32784.196 | K10: 140570.75 | L10: 87002.911 | M10: 66645.339 | N10: 72988.029 | O10: kgs
A11: Assembly Winder | B11: Assembly Winder | C11: 168676.95 | D11: 213602.51 | E11: 219052.09 | F11: 188716.16 | G11: 221290.97 | H11: 209458.64 | I11: 225592.56 | J11: 245198.55 | K11: 363090.72 | L11: 206375.2 | M11: 222987.87 | N11: 183237.85 | O11: kgs
A12: TFO | B12: TFO | C12: 168676.95 | D12: 213602.51 | E12: 219052.09 | F12: 188716.16 | G12: 221290.97 | H12: 209458.64 | I12: 225592.56 | J12: 245198.55 | K12: 363090.72 | L12: 206375.2 | M12: 222987.87 | N12: 183237.85 | O12: kgs
... A25: Tufting | B25: 1/8 Cut | C25: 312281.88 | D25: 204155.64 | E25: 282966.88 | F25: 279914.38 | G25: 251133.58 | H25: 271358.74 | I25: 239213.36 | J25: 248995.68 | K25: 348199.79 | L25: 355959.46 | M25: 268046.12 | N25: 317268.37 | O25: m
A26: Tufting | B26: 1/8 Cut Shifter | O26: m
A27: Tufting | B27: 1/8 Cut Shifter 12 | O27: m
A28: Tufting | B28: 1/8 MLCL | C28: 194493.02 | D28: 185935.82 | E28: 171464.73 | F28: 161996.21 | G28: 182479.17 | H28: 180874.73 | I28: 179649.95 | J28: 173868.51 | K28: 192363.49 | L28: 183034.82 | M28: 186381.86 | N28: 185694.47 | O28: m
A29: Tufting | B29: 3/16 cut | C29: 459611.37 | D29: 482563.21 | E29: 417471.32 | F29: 479893.39 | G29: 498146.98 | H29: 494568.47 | I29: 499387.45 | J29: 317584.63 | K29: 389085.08 | L29: 396245.45 | M29: 406376.55 | N29: 389817.46 | O29: m
A30: Tufting | B30: 3/8 cut | C30: 409675.17 | D30: 267390.98 | E30: 253670.75 | F30: 334033.24 | G30: 582190.52 | H30: 247693.14 | I30: 227907.11 | J30: 159735.33 | K30: 93976.117 | L30: 64120.537 | M30: 63110.992 | N30: 64767.232 | O30: m
A31: Tufting | B31: 5/64 VLOC | C31: 1390.5 | D31: 1878.6041 | E31: 3623.3726 | F31: 2505.3463 | G31: 2678 | H31: 1390.5 | I31: 7063.74 | J31: 2678 | K31: 7230.6 | L31: 1030 | M31: 7436.6 | N31: 10094 | O31: m

Sheet Reqd_MC
A1: Section | B1: Machine | C1: Month | D1: Total Capacity/Day | E1: Total Capacity/Day/MC | F1: BP/Month | G1: BP/Day | H1: Available_MC | I1: Reqd_MC
A2: BCF | B2: BCF | C2: 46113 | D2: 21686.572 | E2: =D2/H2 -> 2710.8215 | F2: =BP_Structured!C2 -> 190053.56 | G2: =F2/DAY(EOMONTH(C2,0)) -> 6335.1186 | H2: 8 | I2: =IF(G2>D2,H2,G2/E2) -> 2.3369737
A3: POY | B3: POY | C3: 46113 | D3: 32121.952 | E3: =D3/H3 -> 2676.8293 | F3: =BP_Structured!C6 -> 1518410 | G3: =F3/DAY(EOMONTH(C3,0)) -> 50613.668 | H3: 12 | I3: =IF(G3>D3,H3,G3/E3) -> 12
A4: Texturizing | B4: Texturizing | C4: 46113 | D4: 29388.133 | E4: =D4/H4 -> 3673.5166 | F4: =BP_Structured!C7 -> 1442558.3 | G4: =F4/DAY(EOMONTH(C4,0)) -> 48085.277 | H4: 8 | I4: =IF(G4>D4,H4,G4/E4) -> 8
A5: Parallel Winding | B5: Parallel Winding | C5: 46113 | D5: 14098.76 | E5: =D5/H5 -> 3524.69 | F5: =BP_Structured!C8 -> 772731.27 | G5: =F5/DAY(EOMONTH(C5,0)) -> 25757.709 | H5: 4 | I5: =IF(G5>D5,H5,G5/E5) -> 4
A6: Cabling | B6: Cabling | C6: 46113 | D6: 39644.343 | E6: =D6/H6 -> 2086.5444 | F6: =BP_Structured!C3 -> 1238788.5 | G6: =F6/DAY(EOMONTH(C6,0)) -> 41292.949 | H6: 19 | I6: =IF(G6>D6,H6,G6/E6) -> 19
A7: Heat Set | B7: Superba Heat Set | C7: 46113 | D7: 36510.72 | E7: =D7/H7 -> 7302.1439 | F7: =BP_Structured!C5 -> 1108335.2 | G7: =F7/DAY(EOMONTH(C7,0)) -> 36944.506 | H7: 5 | I7: =IF(G7>D7,H7,G7/E7) -> 5
A8: Heat Set | B8: Power Heat Set | C8: 46113 | D8: 8671.7067 | E8: =D8/H8 -> 8671.7067 | F8: =BP_Structured!C4 -> 100470.29 | G8: =F8/DAY(EOMONTH(C8,0)) -> 3349.0098 | H8: 1 | I8: =IF(G8>D8,H8,G8/E8) -> 0.38619961
A9: Printing | B9: Printing-Chromojet | C9: 46113 | D9: 3314.4422 | E9: =D9/H9 -> 3314.4422 | F9: =BP_Structured!C13 -> 112252.91 | G9: =F9/DAY(EOMONTH(C9,0)) -> 3741.7637 | H9: 1 | I9: =IF(G9>D9,H9,G9/E9) -> 1
A10: Printing | B10: Printing-Digital | C10: 46113 | D10: 2480.0256 | E10: =D10/H10 -> 2480.0256 | F10: =BP_Structured!C14 -> 24776.395 | G10: =F10/DAY(EOMONTH(C10,0)) -> 825.87982 | H10: 1 | I10: =IF(G10>D10,H10,G10/E10) -> 0.33301262
A11: Coating | B11: Carpet Tiles | C11: 46113 | D11: 14758.225 | E11: =D11/H11 -> 14758.225 | F11: =BP_Structured!C15 -> 96326.288 | G11: =F11/DAY(EOMONTH(C11,0)) -> 3210.8763 | H11: 1 | I11: =IF(G11>D11,H11,G11/E11) -> 0.21756521
A12: Coating | B12: W2W | C12: 46113 | D12: 19608.37 | E12: =D12/H12 -> 19608.37 | F12: =BP_Structured!C16 -> 129572.2 | G12: =F12/DAY(EOMONTH(C12,0)) -> 4319.0735 | H12: 1 | I12: =IF(G12>D12,H12,G12/E12) -> 0.22026683
A13: COPs | B13: COPs | C13: 46113 | D13: 8432.052 | E13: =D13/H13 -> 2108.013 | F13: =BP_Structured!C17 -> 96546.648 | G13: =F13/DAY(EOMONTH(C13,0)) -> 3218.2216 | H13: 4 | I13: =IF(G13>D13,H13,G13/E13) -> 1.5266612
A14: PTST | B14: PTST | C14: 46113 | D14: 6355.8246 | E14: =D14/H14 -> 423.72164 | F14: =BP_Structured!C18 -> 96546.648 | G14: =F14/DAY(EOMONTH(C14,0)) -> 3218.2216 | H14: 15 | I14: =IF(G14>D14,H14,G14/E14) -> 7.5951316
A15: Assembly Winder | B15: Assembly Winder | C15: 46113 | D15: 21534.376 | E15: =D15/H15 -> 5383.5939 | F15: =BP_Structured!C11 -> 168676.95 | G15: =F15/DAY(EOMONTH(C15,0)) -> 5622.565 | H15: 4 | I15: =ROUNDUP(IF(G15>D15,H15,G15/E15),0) -> 2
A16: TFO | B16: TFO | C16: 46113 | D16: 11869.222 | E16: =D16/H16 -> 2373.8444 | F16: =BP_Structured!C12 -> 168676.95 | G16: =F16/DAY(EOMONTH(C16,0)) -> 5622.565 | H16: 5 | I16: =ROUNDUP(IF(G16>D16,H16,G16/E16),0) -> 3
A17: Autoclave | B17: Autoclave | C17: 46113 | D17: 7570.8155 | E17: =D17/H17 -> 7570.8155 | F17: =BP_Structured!C10 -> 72130.301 | G17: =F17/DAY(EOMONTH(C17,0))+101 -> 2505.3434 | H17: 1 | I17: =IF(G17>D17,H17,G17/E17) -> 0.3309212
A18: Multiply | B18: Multiply | C18: 46113 | D18: 11869.222 | E18: =D18/H18 -> #DIV/0! | F18: =BP_Structured!C9 -> 96546.648 | G18: =F18/DAY(EOMONTH(C18,0)) -> 3218.2216 | I18: =IF(G18>D18,H18,G18/E18) -> #DIV/0!
A19: Tufting | B19: 1/10 Cutpile | C19: 46113 | D19: 3036.5253 | E19: =D19/H19 -> 3036.5253 | F19: =BP_Structured!C20 -> 48046.268 | G19: =F19/DAY(EOMONTH(C19,0)) -> 1601.5423 | H19: 1 | I19: =IF(G19>D19,H19,G19/E19) -> 0.52742596
A20: Tufting | B20: 1/10 Infinity | C20: 46113 | D20: 3608.7737 | E20: =D20/H20 -> 3608.7737 | F20: =BP_Structured!C21 -> 38977.965 | G20: =F20/DAY(EOMONTH(C20,0)) -> 1299.2655 | H20: 1 | I20: =IF(G20>D20,H20,G20/E20) -> 0.36002964
A21: Tufting | B21: 1/10 loop | C21: 46113 | D21: 4346.1835 | E21: =D21/H21 -> 4346.1835 | F21: =BP_Structured!C22 -> 41310.012 | G21: =F21/DAY(EOMONTH(C21,0)) -> 1377.0004 | H21: 1 | I21: =IF(G21>D21,H21,G21/E21) -> 0.31682979
A22: Tufting | B22: 1/12 Infinity | C22: 46113 | D22: 1528.5668 | E22: =D22/H22 -> 1528.5668 | F22: =BP_Structured!C23 -> 54425.197 | G22: =F22/DAY(EOMONTH(C22,0)) -> 1814.1732 | H22: 1 | I22: =IF(G22>D22,H22,G22/E22) -> 1
A23: Tufting | B23: 1/12 Rainbow | C23: 46113 | D23: 2237.4397 | E23: =D23/H23 -> 2237.4397 | F23: =BP_Structured!C24 -> 850.67236 | G23: =F23/DAY(EOMONTH(C23,0)) -> 28.355745 | H23: 1 | I23: =IF(G23>D23,H23,G23/E23) -> 0.012673301
A24: Tufting | B24: 1/8 Cut | C24: 46113 | D24: 3208.0937 | E24: =D24/H24 -> 802.02341 | F24: =BP_Structured!C25 -> 312281.88 | G24: =F24/DAY(EOMONTH(C24,0)) -> 10409.396 | H24: 4 | I24: =IF(G24>D24,H24,G24/E24) -> 4
A25: Tufting | B25: 1/8 Cut Shifter | C25: 46113 | E25: =D25/H25 -> #DIV/0! | F25: =BP_Structured!C26 -> 0 | G25: =F25/DAY(EOMONTH(C25,0)) -> 0 | I25: =IF(G25>D25,H25,G25/E25) -> #DIV/0!
A26: Tufting | B26: 1/8 Cut Shifter 12 | C26: 46113 | E26: =D26/H26 -> #DIV/0! | F26: =BP_Structured!C27 -> 0 | G26: =F26/DAY(EOMONTH(C26,0)) -> 0 | I26: =IF(G26>D26,H26,G26/E26) -> #DIV/0!
A27: Tufting | B27: 1/8 MLCL | C27: 46113 | D27: 2460.9525 | E27: =D27/H27 -> 1230.4763 | F27: =BP_Structured!C28 -> 194493.02 | G27: =F27/DAY(EOMONTH(C27,0)) -> 6483.1005 | H27: 2 | I27: =IF(G27>D27,H27,G27/E27) -> 2
A28: Tufting | B28: 3/16 cut | C28: 46113 | D28: 5656.1849 | E28: =D28/H28 -> 1414.0462 | F28: =BP_Structured!C29 -> 459611.37 | G28: =F28/DAY(EOMONTH(C28,0)) -> 15320.379 | H28: 4 | I28: =IF(G28>D28,H28,G28/E28) -> 4
A29: Tufting | B29: 3/8 cut | C29: 46113 | D29: 2748.5789 | E29: =D29/H29 -> 1374.2895 | F29: =BP_Structured!C30 -> 409675.17 | G29: =F29/DAY(EOMONTH(C29,0)) -> 13655.839 | H29: 2 | I29: =IF(G29>D29,H29,G29/E29) -> 2
A30: Tufting | B30: 5/64 VLOC | C30: 46113 | D30: 2908.6716 | E30: =D30/H30 -> 2908.6716 | F30: =BP_Structured!C31 -> 1390.5 | G30: =F30/DAY(EOMONTH(C30,0)) -> 46.35 | H30: 1 | I30: =IF(G30>D30,H30,G30/E30) -> 0.015935109
A31: CSP | B31: Length Cutting | C31: 46113 | E31: 7258 | H31: 1
A32: CSP | B32: Length Overedging | C32: 46113 | E32: 7085 | H32: 2
A33: CSP | B33: Cross Cutting | C33: 46113 | E33: 18432 | H33: 1
A34: CSP | B34: Combiline | C34: 46113 | E34: 3000 | H34: 2
A35: CSP | B35: Table Cutting | C35: 46113 | E35: 5990 | H35: 2
A36: CSP | B36: Manual Overedging | C36: 46113 | E36: 1200/600 | H36: 6
A37: CSP | B37: Bar Tak | C37: 46113 | E37: 3400/1800 | H37: 4
A38: CSP | B38: Packing Line | C38: 46113 | E38: 3600/1300 | H38: 4
